Traceback (most recent call last):
  File "/nfs/scistore19/alistgrp/apanfero/GPTAQ/.conda/lib/python3.10/site-packages/huggingface_hub/utils/_errors.py", line 304, in hf_raise_for_status
    response.raise_for_status()
  File "/nfs/scistore19/alistgrp/apanfero/GPTAQ/.conda/lib/python3.10/site-packages/requests/models.py", line 1021, in raise_for_status
    raise HTTPError(http_error_msg, response=self)
requests.exceptions.HTTPError: 403 Client Error: Forbidden for url: https://huggingface.co/meta-llama/Meta-Llama-3.1-8B/resolve/main/config.json
The above exception was the direct cause of the following exception:
Traceback (most recent call last):
  File "/nfs/scistore19/alistgrp/apanfero/GPTAQ/.conda/lib/python3.10/site-packages/transformers/utils/hub.py", line 402, in cached_file
    resolved_file = hf_hub_download(
  File "/nfs/scistore19/alistgrp/apanfero/GPTAQ/.conda/lib/python3.10/site-packages/huggingface_hub/utils/_deprecation.py", line 101, in inner_f
    return f(*args, **kwargs)
  File "/nfs/scistore19/alistgrp/apanfero/GPTAQ/.conda/lib/python3.10/site-packages/huggingface_hub/utils/_validators.py", line 114, in _inner_fn
    return fn(*args, **kwargs)
  File "/nfs/scistore19/alistgrp/apanfero/GPTAQ/.conda/lib/python3.10/site-packages/huggingface_hub/file_download.py", line 1240, in hf_hub_download
    return _hf_hub_download_to_cache_dir(
  File "/nfs/scistore19/alistgrp/apanfero/GPTAQ/.conda/lib/python3.10/site-packages/huggingface_hub/file_download.py", line 1347, in _hf_hub_download_to_cache_dir
    _raise_on_head_call_error(head_call_error, force_download, local_files_only)
  File "/nfs/scistore19/alistgrp/apanfero/GPTAQ/.conda/lib/python3.10/site-packages/huggingface_hub/file_download.py", line 1854, in _raise_on_head_call_error
    raise head_call_error
  File "/nfs/scistore19/alistgrp/apanfero/GPTAQ/.conda/lib/python3.10/site-packages/huggingface_hub/file_download.py", line 1751, in _get_metadata_or_catch_error
    metadata = get_hf_file_metadata(
  File "/nfs/scistore19/alistgrp/apanfero/GPTAQ/.conda/lib/python3.10/site-packages/huggingface_hub/utils/_validators.py", line 114, in _inner_fn
    return fn(*args, **kwargs)
  File "/nfs/scistore19/alistgrp/apanfero/GPTAQ/.conda/lib/python3.10/site-packages/huggingface_hub/file_download.py", line 1673, in get_hf_file_metadata
    r = _request_wrapper(
  File "/nfs/scistore19/alistgrp/apanfero/GPTAQ/.conda/lib/python3.10/site-packages/huggingface_hub/file_download.py", line 376, in _request_wrapper
    response = _request_wrapper(
  File "/nfs/scistore19/alistgrp/apanfero/GPTAQ/.conda/lib/python3.10/site-packages/huggingface_hub/file_download.py", line 400, in _request_wrapper
    hf_raise_for_status(response)
  File "/nfs/scistore19/alistgrp/apanfero/GPTAQ/.conda/lib/python3.10/site-packages/huggingface_hub/utils/_errors.py", line 321, in hf_raise_for_status
    raise GatedRepoError(message, response) from e
huggingface_hub.utils._errors.GatedRepoError: 403 Client Error. (Request ID: Root=1-66bb5045-7239034f7eeba99e432cea16;3c03bfff-ff1a-497f-856c-8fee9c653686)
Cannot access gated repo for url https://huggingface.co/meta-llama/Meta-Llama-3.1-8B/resolve/main/config.json.
Your request to access model meta-llama/Meta-Llama-3.1-8B has been rejected by the repo's authors.
The above exception was the direct cause of the following exception:
Traceback (most recent call last):
  File "/nfs/scistore19/alistgrp/apanfero/linear-layer-compression/Andrei/gptq/llama2_zeroshot_edenn.py", line 180, in <module>
    model = AutoModelForCausalLM.from_pretrained(args.model, torch_dtype='auto', low_cpu_mem_usage=True)
  File "/nfs/scistore19/alistgrp/apanfero/GPTAQ/.conda/lib/python3.10/site-packages/transformers/models/auto/auto_factory.py", line 524, in from_pretrained
    config, kwargs = AutoConfig.from_pretrained(
  File "/nfs/scistore19/alistgrp/apanfero/GPTAQ/.conda/lib/python3.10/site-packages/transformers/models/auto/configuration_auto.py", line 976, in from_pretrained
    config_dict, unused_kwargs = PretrainedConfig.get_config_dict(pretrained_model_name_or_path, **kwargs)
  File "/nfs/scistore19/alistgrp/apanfero/GPTAQ/.conda/lib/python3.10/site-packages/transformers/configuration_utils.py", line 632, in get_config_dict
    config_dict, kwargs = cls._get_config_dict(pretrained_model_name_or_path, **kwargs)
  File "/nfs/scistore19/alistgrp/apanfero/GPTAQ/.conda/lib/python3.10/site-packages/transformers/configuration_utils.py", line 689, in _get_config_dict
    resolved_config_file = cached_file(
  File "/nfs/scistore19/alistgrp/apanfero/GPTAQ/.conda/lib/python3.10/site-packages/transformers/utils/hub.py", line 420, in cached_file
    raise EnvironmentError(
OSError: You are trying to access a gated repo.
Make sure to have access to it at https://huggingface.co/meta-llama/Meta-Llama-3.1-8B.
403 Client Error. (Request ID: Root=1-66bb5045-7239034f7eeba99e432cea16;3c03bfff-ff1a-497f-856c-8fee9c653686)
Cannot access gated repo for url https://huggingface.co/meta-llama/Meta-Llama-3.1-8B/resolve/main/config.json.
Your request to access model meta-llama/Meta-Llama-3.1-8B has been rejected by the repo's authors.